<?xml version="1.0" encoding="utf-8"?>
<!-- This URDF was automatically created by SolidWorks to URDF Exporter! Originally created by Stephen Brawner (brawner@gmail.com) 
     Commit Version: 1.6.0-1-g15f4949  Build Version: 1.6.7594.29634
     For more information, please see http://wiki.ros.org/sw_urdf_exporter -->
<robot
  name="bigmama0322">
  <link
    name="Link_0">
    <inertial>
      <origin
        xyz="-0.0037804 -0.0092539 0.032475"
        rpy="0 0 0" />
      <mass
        value="0.77237" />
      <inertia
        ixx="0.0014802"
        ixy="-1.2948E-05"
        ixz="1.4235E-05"
        iyy="0.0014381"
        iyz="-7.5223E-06"
        izz="0.0010127" />
    </inertial>
    <visual>
      <origin
        xyz="0 0 0"
        rpy="0 0 0" />
      <geometry>
        <mesh
          filename="package://bigmama0322/meshes/Link_0.STL" />
      </geometry>
      <material
        name="">
        <color
          rgba="0.79216 0.81961 0.93333 1" />
      </material>
    </visual>
    <collision>
      <origin
        xyz="0 0 0"
        rpy="0 0 0" />
      <geometry>
        <mesh
          filename="package://bigmama0322/meshes/Link_0.STL" />
      </geometry>
    </collision>
  </link>
  <link
    name="Link_1">
    <inertial>
      <origin
        xyz="1.1102E-16 0.12 0.014813"
        rpy="0 0 0" />
      <mass
        value="0.28238" />
      <inertia
        ixx="0.0027445"
        ixy="2.7687E-20"
        ixz="1.1384E-20"
        iyy="0.00019508"
        iyz="-3.8961E-20"
        izz="0.0029159" />
    </inertial>
    <visual>
      <origin
        xyz="0 0 0"
        rpy="0 0 0" />
      <geometry>
        <mesh
          filename="package://bigmama0322/meshes/Link_1.STL" />
      </geometry>
      <material
        name="">
        <color
          rgba="0.79216 0.81961 0.93333 1" />
      </material>
    </visual>
    <collision>
      <origin
        xyz="0 0 0"
        rpy="0 0 0" />
      <geometry>
        <mesh
          filename="package://bigmama0322/meshes/Link_1.STL" />
      </geometry>
    </collision>
  </link>
  <joint
    name="Joint_1"
    type="revolute">
    <origin
      xyz="0.022 0 0.155"
      rpy="1.5708 0 1.5708" />
    <parent
      link="Link_0" />
    <child
      link="Link_1" />
    <axis
      xyz="0 0 -1" />
    <limit
      lower="-3.14"
      upper="3.14"
      effort="100"
      velocity="0.25" />
  </joint>
  <link
    name="Link_2">
    <inertial>
      <origin
        xyz="0 0.098184 -0.051898"
        rpy="0 0 0" />
      <mass
        value="0.34516" />
      <inertia
        ixx="0.0036332"
        ixy="3.4036E-18"
        ixz="-4.7012E-19"
        iyy="0.00034405"
        iyz="0.00024115"
        izz="0.0037914" />
    </inertial>
    <visual>
      <origin
        xyz="0 0 0"
        rpy="0 0 0" />
      <geometry>
        <mesh
          filename="package://bigmama0322/meshes/Link_2.STL" />
      </geometry>
      <material
        name="">
        <color
          rgba="0.79216 0.81961 0.93333 1" />
      </material>
    </visual>
    <collision>
      <origin
        xyz="0 0 0"
        rpy="0 0 0" />
      <geometry>
        <mesh
          filename="package://bigmama0322/meshes/Link_2.STL" />
      </geometry>
    </collision>
  </link>
  <joint
    name="Joint_2"
    type="revolute">
    <origin
      xyz="0 0.24 0"
      rpy="0 0 0" />
    <parent
      link="Link_1" />
    <child
      link="Link_2" />
    <axis
      xyz="0 0 -1" />
    <limit
      lower="-3.14"
      upper="3.14"
      effort="100"
      velocity="0.25" />
  </joint>
  <link
    name="Link_3">
    <inertial>
      <origin
        xyz="0.018256 0.077688 0.029219"
        rpy="0 0 0" />
      <mass
        value="0.40524" />
      <inertia
        ixx="0.0010067"
        ixy="-1.0212E-05"
        ixz="-1.2958E-05"
        iyy="0.00027741"
        iyz="1.4235E-05"
        izz="0.0011025" />
    </inertial>
    <visual>
      <origin
        xyz="0 0 0"
        rpy="0 0 0" />
      <geometry>
        <mesh
          filename="package://bigmama0322/meshes/Link_3.STL" />
      </geometry>
      <material
        name="">
        <color
          rgba="0.79216 0.81961 0.93333 1" />
      </material>
    </visual>
    <collision>
      <origin
        xyz="0 0 0"
        rpy="0 0 0" />
      <geometry>
        <mesh
          filename="package://bigmama0322/meshes/Link_3.STL" />
      </geometry>
    </collision>
  </link>
  <joint
    name="Joint_3"
    type="revolute">
    <origin
      xyz="0 0.24 -0.0442"
      rpy="0 0 0" />
    <parent
      link="Link_2" />
    <child
      link="Link_3" />
    <axis
      xyz="0 0 1" />
    <limit
      lower="-3.14"
      upper="3.14"
      effort="100"
      velocity="0.25" />
  </joint>
  <link
    name="Link_4">
    <inertial>
      <origin
        xyz="-0.03035 -2.1919E-05 -0.024835"
        rpy="0 0 0" />
      <mass
        value="0.28366" />
      <inertia
        ixx="0.00039469"
        ixy="1.3573E-08"
        ixz="-2.4944E-06"
        iyy="0.00034528"
        iyz="7.1348E-09"
        izz="0.00068966" />
    </inertial>
    <visual>
      <origin
        xyz="0 0 0"
        rpy="0 0 0" />
      <geometry>
        <mesh
          filename="package://bigmama0322/meshes/Link_4.STL" />
      </geometry>
      <material
        name="">
        <color
          rgba="0.79216 0.81961 0.93333 1" />
      </material>
    </visual>
    <collision>
      <origin
        xyz="0 0 0"
        rpy="0 0 0" />
      <geometry>
        <mesh
          filename="package://bigmama0322/meshes/Link_4.STL" />
      </geometry>
    </collision>
  </link>
  <joint
    name="Joint_4"
    type="revolute">
    <origin
      xyz="0 0.145 0.022"
      rpy="1.5708 0 0" />
    <parent
      link="Link_3" />
    <child
      link="Link_4" />
    <axis
      xyz="0 0 -1" />
    <limit
      lower="-0.0001"
      upper="0.0001"
      effort="0.0001"
      velocity="0.0001" />
  </joint>
  <link
    name="Link_forwardsucker">
    <inertial>
      <origin
        xyz="0.00022659 1.6931E-08 0.00041075"
        rpy="0 0 0" />
      <mass
        value="0.083395" />
      <inertia
        ixx="3.6333E-05"
        ixy="6.1527E-10"
        ixz="-1.8118E-07"
        iyy="3.2047E-05"
        iyz="3.9595E-12"
        izz="4.558E-05" />
    </inertial>
    <visual>
      <origin
        xyz="0 0 0"
        rpy="0 0 0" />
      <geometry>
        <mesh
          filename="package://bigmama0322/meshes/Link_forwardsucker.STL" />
      </geometry>
      <material
        name="">
        <color
          rgba="0.79216 0.81961 0.93333 1" />
      </material>
    </visual>
    <collision>
      <origin
        xyz="0 0 0"
        rpy="0 0 0" />
      <geometry>
        <mesh
          filename="package://bigmama0322/meshes/Link_forwardsucker.STL" />
      </geometry>
    </collision>
  </link>
  <joint
    name="Joint_forwardsucker"
    type="revolute">
    <origin
      xyz="0.1 0 -0.035"
      rpy="0 0 0" />
    <parent
      link="Link_4" />
    <child
      link="Link_forwardsucker" />
    <axis
      xyz="0 0 -1" />
    <limit
      lower="-0.0001"
      upper="0.0001"
      effort="0.0001"
      velocity="0.0001" />
  </joint>
  <link
    name="Link_innerfinger">
    <inertial>
      <origin
        xyz="-0.0081162 -1.3867E-13 0.004"
        rpy="0 0 0" />
      <mass
        value="0.0014267" />
      <inertia
        ixx="2.0947E-08"
        ixy="3.6535E-23"
        ixz="2.1657E-23"
        iyy="4.4699E-08"
        iyz="-1.0093E-24"
        izz="5.0429E-08" />
    </inertial>
    <visual>
      <origin
        xyz="0 0 0"
        rpy="0 0 0" />
      <geometry>
        <mesh
          filename="package://bigmama0322/meshes/Link_innerfinger.STL" />
      </geometry>
      <material
        name="">
        <color
          rgba="0.79216 0.81961 0.93333 1" />
      </material>
    </visual>
    <collision>
      <origin
        xyz="0 0 0"
        rpy="0 0 0" />
      <geometry>
        <mesh
          filename="package://bigmama0322/meshes/Link_innerfinger.STL" />
      </geometry>
    </collision>
  </link>
  <joint
    name="Joint_innerfinger"
    type="prismatic">
    <origin
      xyz="0 -0.006 -0.015"
      rpy="0 0 1.5708" />
    <parent
      link="Link_forwardsucker" />
    <child
      link="Link_innerfinger" />
    <axis
      xyz="-1 0 0" />
    <limit
      lower="-0.002"
      upper="0.002"
      effort="50"
      velocity="0.005" />
  </joint>
  <link
    name="Link_exterfinger">
    <inertial>
      <origin
        xyz="-0.0081162 1.3101E-13 0.004"
        rpy="0 0 0" />
      <mass
        value="0.0014267" />
      <inertia
        ixx="2.0947E-08"
        ixy="1.7845E-22"
        ixz="1.2451E-22"
        iyy="4.4699E-08"
        iyz="-2.5106E-26"
        izz="5.0429E-08" />
    </inertial>
    <visual>
      <origin
        xyz="0 0 0"
        rpy="0 0 0" />
      <geometry>
        <mesh
          filename="package://bigmama0322/meshes/Link_exterfinger.STL" />
      </geometry>
      <material
        name="">
        <color
          rgba="0.79216 0.81961 0.93333 1" />
      </material>
    </visual>
    <collision>
      <origin
        xyz="0 0 0"
        rpy="0 0 0" />
      <geometry>
        <mesh
          filename="package://bigmama0322/meshes/Link_exterfinger.STL" />
      </geometry>
    </collision>
  </link>
  <joint
    name="Joint_exterfinger"
    type="prismatic">
    <origin
      xyz="0 0.006 -0.015"
      rpy="0 0 -1.5708" />
    <parent
      link="Link_forwardsucker" />
    <child
      link="Link_exterfinger" />
    <axis
      xyz="1 0 0" />
    <limit
      lower="-0.002"
      upper="0.002"
      effort="50"
      velocity="0.005" />
  </joint>
</robot>