<?xml version="1.0" encoding="utf-8"?>
<!-- This URDF was automatically created by SolidWorks to URDF Exporter! Originally created by Stephen Brawner (brawner@gmail.com) 
     Commit Version: 1.6.0-1-g15f4949  Build Version: 1.6.7594.29634
     For more information, please see http://wiki.ros.org/sw_urdf_exporter -->
<robot
  name="bigmama0410">
  <link
    name="Link_0">
    <inertial>
      <origin
        xyz="-0.0036007 -0.0088372 0.029242"
        rpy="0 0 0" />
      <mass
        value="0.81093" />
      <inertia
        ixx="0.0014988"
        ixy="-1.2947E-05"
        ixz="1.4235E-05"
        iyy="0.0014451"
        iyz="-7.3423E-06"
        izz="0.0010295" />
    </inertial>
    <visual>
      <origin
        xyz="0 0 0"
        rpy="0 0 0" />
      <geometry>
        <mesh
          filename="package://bigmama0410/meshes/Link_0.STL" />
      </geometry>
      <material
        name="">
        <color
          rgba="0.79216 0.81961 0.93333 1" />
      </material>
    </visual>
    <collision>
      <origin
        xyz="0 0 0"
        rpy="0 0 0" />
      <geometry>
        <mesh
          filename="package://bigmama0410/meshes/Link_0.STL" />
      </geometry>
    </collision>
  </link>
  <link
    name="Link_1">
    <inertial>
      <origin
        xyz="3.33066907387547E-16 0.120000000000001 0.0148133941875559"
        rpy="0 0 0" />
      <mass
        value="0.282384693513863" />
      <inertia
        ixx="0.00274447139440248"
        ixy="3.01436980823378E-20"
        ixz="-5.79015856992731E-21"
        iyy="0.000195078787164715"
        iyz="3.72472007863815E-21"
        izz="0.00291591183814071" />
    </inertial>
    <visual>
      <origin
        xyz="0 0 0"
        rpy="0 0 0" />
      <geometry>
        <mesh
          filename="package://bigmama0410/meshes/Link_1.STL" />
      </geometry>
      <material
        name="">
        <color
          rgba="0.792156862745098 0.819607843137255 0.933333333333333 1" />
      </material>
    </visual>
    <collision>
      <origin
        xyz="0 0 0"
        rpy="0 0 0" />
      <geometry>
        <mesh
          filename="package://bigmama0410/meshes/Link_1.STL" />
      </geometry>
    </collision>
  </link>
  <joint
    name="Joint_1"
    type="revolute">
    <origin
      xyz="0.022 0 0.155"
      rpy="1.5708 0 1.5708" />
    <parent
      link="Link_0" />
    <child
      link="Link_1" />
    <axis
      xyz="0 0 -1" />
    <limit
      lower="-3.14"
      upper="3.14"
      effort="500"
      velocity="0.05" />
  </joint>
  <link
    name="Link_2">
    <inertial>
      <origin
        xyz="5.6621374255883E-15 0.0981842440812921 -0.0518979671215241"
        rpy="0 0 0" />
      <mass
        value="0.345163663974144" />
      <inertia
        ixx="0.0036331910417201"
        ixy="3.25445760375702E-18"
        ixz="-4.51375745496694E-19"
        iyy="0.000344054038167575"
        iyz="0.000241150545790953"
        izz="0.00379142507539423" />
    </inertial>
    <visual>
      <origin
        xyz="0 0 0"
        rpy="0 0 0" />
      <geometry>
        <mesh
          filename="package://bigmama0410/meshes/Link_2.STL" />
      </geometry>
      <material
        name="">
        <color
          rgba="0.792156862745098 0.819607843137255 0.933333333333333 1" />
      </material>
    </visual>
    <collision>
      <origin
        xyz="0 0 0"
        rpy="0 0 0" />
      <geometry>
        <mesh
          filename="package://bigmama0410/meshes/Link_2.STL" />
      </geometry>
    </collision>
  </link>
  <joint
    name="Joint_2"
    type="revolute">
    <origin
      xyz="0 0.24 0"
      rpy="0 0 0" />
    <parent
      link="Link_1" />
    <child
      link="Link_2" />
    <axis
      xyz="0 0 -1" />
    <limit
      lower="-3.14"
      upper="3.14"
      effort="500"
      velocity="0.05" />
  </joint>
  <link
    name="Link_3">
    <inertial>
      <origin
        xyz="0.0182556388647203 0.077688167435717 0.0292189539257218"
        rpy="0 0 0" />
      <mass
        value="0.405243678629156" />
      <inertia
        ixx="0.0010066908609712"
        ixy="-1.02117053661611E-05"
        ixz="-1.29579969608816E-05"
        iyy="0.000277409370252715"
        iyz="1.42352093688466E-05"
        izz="0.00110247571714619" />
    </inertial>
    <visual>
      <origin
        xyz="0 0 0"
        rpy="0 0 0" />
      <geometry>
        <mesh
          filename="package://bigmama0410/meshes/Link_3.STL" />
      </geometry>
      <material
        name="">
        <color
          rgba="0.792156862745098 0.819607843137255 0.933333333333333 1" />
      </material>
    </visual>
    <collision>
      <origin
        xyz="0 0 0"
        rpy="0 0 0" />
      <geometry>
        <mesh
          filename="package://bigmama0410/meshes/Link_3.STL" />
      </geometry>
    </collision>
  </link>
  <joint
    name="Joint_3"
    type="revolute">
    <origin
      xyz="0 0.24 -0.0442"
      rpy="0 0 0" />
    <parent
      link="Link_2" />
    <child
      link="Link_3" />
    <axis
      xyz="0 0 1" />
    <limit
      lower="-3.14"
      upper="3.14"
      effort="500"
      velocity="0.05" />
  </joint>
  <link
    name="Link_4">
    <inertial>
      <origin
        xyz="-0.000571100099163169 -1.5325519683182E-05 -0.0288070807646196"
        rpy="0 0 0" />
      <mass
        value="0.405610108151776" />
      <inertia
        ixx="0.000438080420431632"
        ixy="1.3288211401117E-08"
        ixz="-2.85557702463614E-06"
        iyy="0.000395912370663264"
        iyz="7.13846572538157E-09"
        izz="0.000752016973569227" />
    </inertial>
    <visual>
      <origin
        xyz="0 0 0"
        rpy="0 0 0" />
      <geometry>
        <mesh
          filename="package://bigmama0410/meshes/Link_4.STL" />
      </geometry>
      <material
        name="">
        <color
          rgba="0.792156862745098 0.819607843137255 0.933333333333333 1" />
      </material>
    </visual>
    <collision>
      <origin
        xyz="0 0 0"
        rpy="0 0 0" />
      <geometry>
        <mesh
          filename="package://bigmama0410/meshes/Link_4.STL" />
      </geometry>
    </collision>
  </link>
  <joint
    name="Joint_4"
    type="revolute">
    <origin
      xyz="0 0.145 0.022"
      rpy="1.5708 0 0" />
    <parent
      link="Link_3" />
    <child
      link="Link_4" />
    <axis
      xyz="0 0 -1" />
    <limit
      lower="0"
      upper="1E-05"
      effort="1E-05"
      velocity="1E-05" />
  </joint>
  <link
    name="Link_innerfinger">
    <inertial>
      <origin
        xyz="-0.72342 0.62118 -0.012901"
        rpy="0 0 0" />
      <mass
        value="0.11337" />
      <inertia
        ixx="0.021903"
        ixy="0.013168"
        ixz="0.0010521"
        iyy="0.01296"
        iyz="-0.0012624"
        izz="0.03005" />
    </inertial>
    <visual>
      <origin
        xyz="0 0 0"
        rpy="0 0 0" />
      <geometry>
        <mesh
          filename="package://bigmama0410/meshes/Link_innerfinger.STL" />
      </geometry>
      <material
        name="">
        <color
          rgba="0.79216 0.81961 0.93333 1" />
      </material>
    </visual>
    <collision>
      <origin
        xyz="0 0 0"
        rpy="0 0 0" />
      <geometry>
        <mesh
          filename="package://bigmama0410/meshes/Link_innerfinger.STL" />
      </geometry>
    </collision>
  </link>
  <joint
    name="Joint_innerfinger"
    type="revolute">
    <origin
      xyz="-0.005 -0.11247 0"
      rpy="-1.5708 0 1.5708" />
    <parent
      link="Link_4" />
    <child
      link="Link_innerfinger" />
    <axis
      xyz="0 0 -1" />
    <limit
      lower="-3.14"
      upper="3.14"
      effort="500"
      velocity="0.05" />
  </joint>
  <link
    name="Link_exterfinger">
    <inertial>
      <origin
        xyz="0.72342 0.62118 -0.012901"
        rpy="0 0 0" />
      <mass
        value="0.11337" />
      <inertia
        ixx="0.021903"
        ixy="-0.013168"
        ixz="-0.0010521"
        iyy="0.01296"
        iyz="-0.0012624"
        izz="0.03005" />
    </inertial>
    <visual>
      <origin
        xyz="0 0 0"
        rpy="0 0 0" />
      <geometry>
        <mesh
          filename="package://bigmama0410/meshes/Link_exterfinger.STL" />
      </geometry>
      <material
        name="">
        <color
          rgba="0.79216 0.81961 0.93333 1" />
      </material>
    </visual>
    <collision>
      <origin
        xyz="0 0 0"
        rpy="0 0 0" />
      <geometry>
        <mesh
          filename="package://bigmama0410/meshes/Link_exterfinger.STL" />
      </geometry>
    </collision>
  </link>
  <joint
    name="Joint_exterfinger"
    type="revolute">
    <origin
      xyz="-0.005 0.11247 0"
      rpy="-1.5708 0 1.5708" />
    <parent
      link="Link_4" />
    <child
      link="Link_exterfinger" />
    <axis
      xyz="0 0 -1" />
    <limit
      lower="-3.14"
      upper="3.14"
      effort="500"
      velocity="0.05" />
  </joint>
  <link
    name="Link_baseout">
    <inertial>
      <origin
        xyz="-0.72342 -0.62118 0.012901"
        rpy="0 0 0" />
      <mass
        value="0.11337" />
      <inertia
        ixx="0.021903"
        ixy="-0.013168"
        ixz="-0.0010521"
        iyy="0.01296"
        iyz="-0.0012624"
        izz="0.03005" />
    </inertial>
    <visual>
      <origin
        xyz="0 0 0"
        rpy="0 0 0" />
      <geometry>
        <mesh
          filename="package://bigmama0410/meshes/Link_baseout.STL" />
      </geometry>
      <material
        name="">
        <color
          rgba="0.79216 0.81961 0.93333 1" />
      </material>
    </visual>
    <collision>
      <origin
        xyz="0 0 0"
        rpy="0 0 0" />
      <geometry>
        <mesh
          filename="package://bigmama0410/meshes/Link_baseout.STL" />
      </geometry>
    </collision>
  </link>
  <joint
    name="Joint_baseout"
    type="revolute">
    <origin
      xyz="-0.11247 0.005 0.01"
      rpy="1.5708 0 0" />
    <parent
      link="Link_0" />
    <child
      link="Link_baseout" />
    <axis
      xyz="0 0 1" />
    <limit
      lower="-3.14"
      upper="3.14"
      effort="500"
      velocity="0.05" />
  </joint>
  <link
    name="Link_basein">
    <inertial>
      <origin
        xyz="0.72342 -0.62118 0.012901"
        rpy="0 0 0" />
      <mass
        value="0.11337" />
      <inertia
        ixx="0.021903"
        ixy="0.013168"
        ixz="0.0010521"
        iyy="0.01296"
        iyz="-0.0012624"
        izz="0.03005" />
    </inertial>
    <visual>
      <origin
        xyz="0 0 0"
        rpy="0 0 0" />
      <geometry>
        <mesh
          filename="package://bigmama0410/meshes/Link_basein.STL" />
      </geometry>
      <material
        name="">
        <color
          rgba="0.79216 0.81961 0.93333 1" />
      </material>
    </visual>
    <collision>
      <origin
        xyz="0 0 0"
        rpy="0 0 0" />
      <geometry>
        <mesh
          filename="package://bigmama0410/meshes/Link_basein.STL" />
      </geometry>
    </collision>
  </link>
  <joint
    name="Joint_basein"
    type="revolute">
    <origin
      xyz="0.11247 0.005 0.01"
      rpy="1.5708 0 0" />
    <parent
      link="Link_0" />
    <child
      link="Link_basein" />
    <axis
      xyz="0 0 1" />
    <limit
      lower="-3.14"
      upper="3.14"
      effort="500"
      velocity="0.05" />
  </joint>
</robot>