<?xml version="1.0" encoding="utf-8"?>
<!-- This URDF was automatically created by SolidWorks to URDF Exporter! Originally created by Stephen Brawner (brawner@gmail.com) 
     Commit Version: 1.6.0-1-g15f4949  Build Version: 1.6.7594.29634
     For more information, please see http://wiki.ros.org/sw_urdf_exporter -->
<robot
  name="bigmama0401">
  <link
    name="Link_0">
    <inertial>
      <origin
        xyz="-0.0036007 -0.0088372 0.029242"
        rpy="0 0 0" />
      <mass
        value="0.81093" />
      <inertia
        ixx="0.0014988"
        ixy="-1.2947E-05"
        ixz="1.4235E-05"
        iyy="0.0014451"
        iyz="-7.3423E-06"
        izz="0.0010295" />
    </inertial>
    <visual>
      <origin
        xyz="0 0 0"
        rpy="0 0 0" />
      <geometry>
        <mesh
          filename="package://bigmama0401/meshes/Link_0.STL" />
      </geometry>
      <material
        name="">
        <color
          rgba="0.79216 0.81961 0.93333 1" />
      </material>
    </visual>
    <collision>
      <origin
        xyz="0 0 0"
        rpy="0 0 0" />
      <geometry>
        <mesh
          filename="package://bigmama0401/meshes/Link_0.STL" />
      </geometry>
    </collision>
  </link>
  <link
    name="Link_1">
    <inertial>
      <origin
        xyz="3.1086E-15 0.12 0.014813"
        rpy="0 0 0" />
      <mass
        value="0.28238" />
      <inertia
        ixx="0.0027445"
        ixy="1.3618E-19"
        ixz="-1.819E-21"
        iyy="0.00019508"
        iyz="-9.1226E-21"
        izz="0.0029159" />
    </inertial>
    <visual>
      <origin
        xyz="0 0 0"
        rpy="0 0 0" />
      <geometry>
        <mesh
          filename="package://bigmama0401/meshes/Link_1.STL" />
      </geometry>
      <material
        name="">
        <color
          rgba="0.79216 0.81961 0.93333 1" />
      </material>
    </visual>
    <collision>
      <origin
        xyz="0 0 0"
        rpy="0 0 0" />
      <geometry>
        <mesh
          filename="package://bigmama0401/meshes/Link_1.STL" />
      </geometry>
    </collision>
  </link>
  <joint
    name="Joint_1"
    type="revolute">
    <origin
      xyz="0.022 0 0.155"
      rpy="1.5708 0 1.5708" />
    <parent
      link="Link_0" />
    <child
      link="Link_1" />
    <axis
      xyz="0 0 -1" />
    <limit
      lower="-3.14"
      upper="3.14"
      effort="100"
      velocity="0.25" />
  </joint>
  <link
    name="Link_2">
    <inertial>
      <origin
        xyz="8.2157E-15 0.098184 -0.051898"
        rpy="0 0 0" />
      <mass
        value="0.34516" />
      <inertia
        ixx="0.0036332"
        ixy="3.1442E-18"
        ixz="-4.4392E-19"
        iyy="0.00034405"
        iyz="0.00024115"
        izz="0.0037914" />
    </inertial>
    <visual>
      <origin
        xyz="0 0 0"
        rpy="0 0 0" />
      <geometry>
        <mesh
          filename="package://bigmama0401/meshes/Link_2.STL" />
      </geometry>
      <material
        name="">
        <color
          rgba="0.79216 0.81961 0.93333 1" />
      </material>
    </visual>
    <collision>
      <origin
        xyz="0 0 0"
        rpy="0 0 0" />
      <geometry>
        <mesh
          filename="package://bigmama0401/meshes/Link_2.STL" />
      </geometry>
    </collision>
  </link>
  <joint
    name="Joint_2"
    type="revolute">
    <origin
      xyz="0 0.24 0"
      rpy="0 0 0" />
    <parent
      link="Link_1" />
    <child
      link="Link_2" />
    <axis
      xyz="0 0 -1" />
    <limit
      lower="-3.14"
      upper="3.14"
      effort="100"
      velocity="0.25" />
  </joint>
  <link
    name="Link_3">
    <inertial>
      <origin
        xyz="0.018256 0.077688 0.029219"
        rpy="0 0 0" />
      <mass
        value="0.40524" />
      <inertia
        ixx="0.0010067"
        ixy="-1.0212E-05"
        ixz="-1.2958E-05"
        iyy="0.00027741"
        iyz="1.4235E-05"
        izz="0.0011025" />
    </inertial>
    <visual>
      <origin
        xyz="0 0 0"
        rpy="0 0 0" />
      <geometry>
        <mesh
          filename="package://bigmama0401/meshes/Link_3.STL" />
      </geometry>
      <material
        name="">
        <color
          rgba="0.79216 0.81961 0.93333 1" />
      </material>
    </visual>
    <collision>
      <origin
        xyz="0 0 0"
        rpy="0 0 0" />
      <geometry>
        <mesh
          filename="package://bigmama0401/meshes/Link_3.STL" />
      </geometry>
    </collision>
  </link>
  <joint
    name="Joint_3"
    type="revolute">
    <origin
      xyz="0 0.24 -0.0442"
      rpy="0 0 0" />
    <parent
      link="Link_2" />
    <child
      link="Link_3" />
    <axis
      xyz="0 0 1" />
    <limit
      lower="-3.14"
      upper="3.14"
      effort="100"
      velocity="0.25" />
  </joint>
  <link
    name="Link_4">
    <inertial>
      <origin
        xyz="-0.01848 -1.8063E-05 -0.026214"
        rpy="0 0 0" />
      <mass
        value="0.3443" />
      <inertia
        ixx="0.00040527"
        ixy="1.2985E-08"
        ixz="-2.8556E-06"
        iyy="0.00036433"
        iyz="7.1312E-09"
        izz="0.00070995" />
    </inertial>
    <visual>
      <origin
        xyz="0 0 0"
        rpy="0 0 0" />
      <geometry>
        <mesh
          filename="package://bigmama0401/meshes/Link_4.STL" />
      </geometry>
      <material
        name="">
        <color
          rgba="0.79216 0.81961 0.93333 1" />
      </material>
    </visual>
    <collision>
      <origin
        xyz="0 0 0"
        rpy="0 0 0" />
      <geometry>
        <mesh
          filename="package://bigmama0401/meshes/Link_4.STL" />
      </geometry>
    </collision>
  </link>
  <joint
    name="Joint_4"
    type="revolute">
    <origin
      xyz="0 0.145 0.022"
      rpy="1.5708 0 0" />
    <parent
      link="Link_3" />
    <child
      link="Link_4" />
    <axis
      xyz="0 0 -1" />
    <limit
      lower="-1E-05"
      upper="1E-05"
      effort="1E-05"
      velocity="1E-05" />
  </joint>
  <link
    name="Link_exterfinger">
    <inertial>
      <origin
        xyz="0.016755 -5.9581E-09 -0.0084274"
        rpy="0 0 0" />
      <mass
        value="0.029014" />
      <inertia
        ixx="1.065E-05"
        ixy="1.6581E-11"
        ixz="2.8606E-07"
        iyy="3.3212E-06"
        iyz="-5.7234E-13"
        izz="1.267E-05" />
    </inertial>
    <visual>
      <origin
        xyz="0 0 0"
        rpy="0 0 0" />
      <geometry>
        <mesh
          filename="package://bigmama0401/meshes/Link_exterfinger.STL" />
      </geometry>
      <material
        name="">
        <color
          rgba="0.79216 0.81961 0.93333 1" />
      </material>
    </visual>
    <collision>
      <origin
        xyz="0 0 0"
        rpy="0 0 0" />
      <geometry>
        <mesh
          filename="package://bigmama0401/meshes/Link_exterfinger.STL" />
      </geometry>
    </collision>
  </link>
  <joint
    name="Joint_exterfinger"
    type="prismatic">
    <origin
      xyz="0.1 0 -0.035"
      rpy="0 0 1.5708" />
    <parent
      link="Link_4" />
    <child
      link="Link_exterfinger" />
    <axis
      xyz="1 0 0" />
    <limit
      lower="-0.01"
      upper="0.01"
      effort="500"
      velocity="0.001" />
  </joint>
  <link
    name="Link_innerfinger">
    <inertial>
      <origin
        xyz="-0.016755 5.9581E-09 -0.0084274"
        rpy="0 0 0" />
      <mass
        value="0.029014" />
      <inertia
        ixx="1.065E-05"
        ixy="1.6581E-11"
        ixz="-2.8606E-07"
        iyy="3.3212E-06"
        iyz="5.7234E-13"
        izz="1.267E-05" />
    </inertial>
    <visual>
      <origin
        xyz="0 0 0"
        rpy="0 0 0" />
      <geometry>
        <mesh
          filename="package://bigmama0401/meshes/Link_innerfinger.STL" />
      </geometry>
      <material
        name="">
        <color
          rgba="0.79216 0.81961 0.93333 1" />
      </material>
    </visual>
    <collision>
      <origin
        xyz="0 0 0"
        rpy="0 0 0" />
      <geometry>
        <mesh
          filename="package://bigmama0401/meshes/Link_innerfinger.STL" />
      </geometry>
    </collision>
  </link>
  <joint
    name="Joint_innerfinger"
    type="prismatic">
    <origin
      xyz="0.1 0 -0.035"
      rpy="0 0 1.5708" />
    <parent
      link="Link_4" />
    <child
      link="Link_innerfinger" />
    <axis
      xyz="-1 0 0" />
    <limit
      lower="-0.01"
      upper="0.01"
      effort="500"
      velocity="0.001" />
  </joint>
</robot>