<?xml version="1.0" encoding="utf-8"?>
<!-- This URDF was automatically created by SolidWorks to URDF Exporter! Originally created by Stephen Brawner (brawner@gmail.com) 
     Commit Version: 1.6.0-1-g15f4949  Build Version: 1.6.7594.29634
     For more information, please see http://wiki.ros.org/sw_urdf_exporter -->
<robot
  name="bigmama0314">
  <link
    name="Link_0">
    <inertial>
      <origin
        xyz="-0.0037121 -0.0090866 0.031222"
        rpy="0 0 0" />
      <mass
        value="0.78659" />
      <inertia
        ixx="0.0014841"
        ixy="-1.2946E-05"
        ixz="1.4236E-05"
        iyy="0.0014419"
        iyz="-7.5325E-06"
        izz="0.0010174" />
    </inertial>
    <visual>
      <origin
        xyz="0 0 0"
        rpy="0 0 0" />
      <geometry>
        <mesh
          filename="package://bigmama0314/meshes/Link_0.STL" />
      </geometry>
      <material
        name="">
        <color
          rgba="0.79216 0.81961 0.93333 1" />
      </material>
    </visual>
    <collision>
      <origin
        xyz="0 0 0"
        rpy="0 0 0" />
      <geometry>
        <mesh
          filename="package://bigmama0314/meshes/Link_0.STL" />
      </geometry>
    </collision>
  </link>
  <link
    name="Link_1">
    <inertial>
      <origin
        xyz="-6.6613E-16 0.12 0.014813"
        rpy="0 0 0" />
      <mass
        value="0.28238" />
      <inertia
        ixx="0.0027445"
        ixy="6.4192E-20"
        ixz="-6.9886E-21"
        iyy="0.00019508"
        iyz="-3.8408E-20"
        izz="0.0029159" />
    </inertial>
    <visual>
      <origin
        xyz="0 0 0"
        rpy="0 0 0" />
      <geometry>
        <mesh
          filename="package://bigmama0314/meshes/Link_1.STL" />
      </geometry>
      <material
        name="">
        <color
          rgba="0.79216 0.81961 0.93333 1" />
      </material>
    </visual>
    <collision>
      <origin
        xyz="0 0 0"
        rpy="0 0 0" />
      <geometry>
        <mesh
          filename="package://bigmama0314/meshes/Link_1.STL" />
      </geometry>
    </collision>
  </link>
  <joint
    name="Joint_1"
    type="revolute">
    <origin
      xyz="0.022 0 0.155"
      rpy="1.5708 0 1.5708" />
    <parent
      link="Link_0" />
    <child
      link="Link_1" />
    <axis
      xyz="0 0 -1" />
    <limit
      lower="-3.14"
      upper="3.14"
      effort="100"
      velocity="0.25" />
  </joint>
  <link
    name="Link_2">
    <inertial>
      <origin
        xyz="0 0.098184 -0.051898"
        rpy="0 0 0" />
      <mass
        value="0.34516" />
      <inertia
        ixx="0.0036332"
        ixy="3.2681E-18"
        ixz="-4.5328E-19"
        iyy="0.00034405"
        iyz="0.00024115"
        izz="0.0037914" />
    </inertial>
    <visual>
      <origin
        xyz="0 0 0"
        rpy="0 0 0" />
      <geometry>
        <mesh
          filename="package://bigmama0314/meshes/Link_2.STL" />
      </geometry>
      <material
        name="">
        <color
          rgba="0.79216 0.81961 0.93333 1" />
      </material>
    </visual>
    <collision>
      <origin
        xyz="0 0 0"
        rpy="0 0 0" />
      <geometry>
        <mesh
          filename="package://bigmama0314/meshes/Link_2.STL" />
      </geometry>
    </collision>
  </link>
  <joint
    name="Joint_2"
    type="revolute">
    <origin
      xyz="0 0.24 0"
      rpy="0 0 0" />
    <parent
      link="Link_1" />
    <child
      link="Link_2" />
    <axis
      xyz="0 0 -1" />
    <limit
      lower="-3.14"
      upper="3.14"
      effort="100"
      velocity="0.25" />
  </joint>
  <link
    name="Link_3">
    <inertial>
      <origin
        xyz="0.018256 0.077688 0.029219"
        rpy="0 0 0" />
      <mass
        value="0.40524" />
      <inertia
        ixx="0.0010067"
        ixy="-1.0212E-05"
        ixz="-1.2958E-05"
        iyy="0.00027741"
        iyz="1.4235E-05"
        izz="0.0011025" />
    </inertial>
    <visual>
      <origin
        xyz="0 0 0"
        rpy="0 0 0" />
      <geometry>
        <mesh
          filename="package://bigmama0314/meshes/Link_3.STL" />
      </geometry>
      <material
        name="">
        <color
          rgba="0.79216 0.81961 0.93333 1" />
      </material>
    </visual>
    <collision>
      <origin
        xyz="0 0 0"
        rpy="0 0 0" />
      <geometry>
        <mesh
          filename="package://bigmama0314/meshes/Link_3.STL" />
      </geometry>
    </collision>
  </link>
  <joint
    name="Joint_3"
    type="revolute">
    <origin
      xyz="0 0.24 -0.0442"
      rpy="0 0 0" />
    <parent
      link="Link_2" />
    <child
      link="Link_3" />
    <axis
      xyz="0 0 1" />
    <limit
      lower="-3.14"
      upper="3.14"
      effort="100"
      velocity="0.25" />
  </joint>
  <link
    name="Link_4">
    <inertial>
      <origin
        xyz="-0.030985 -2.1176E-05 -0.025584"
        rpy="0 0 0" />
      <mass
        value="0.29314" />
      <inertia
        ixx="0.00039725"
        ixy="1.2499E-08"
        ixz="-2.474E-06"
        iyy="0.00034787"
        iyz="7.2147E-09"
        izz="0.00069279" />
    </inertial>
    <visual>
      <origin
        xyz="0 0 0"
        rpy="0 0 0" />
      <geometry>
        <mesh
          filename="package://bigmama0314/meshes/Link_4.STL" />
      </geometry>
      <material
        name="">
        <color
          rgba="0.79216 0.81961 0.93333 1" />
      </material>
    </visual>
    <collision>
      <origin
        xyz="0 0 0"
        rpy="0 0 0" />
      <geometry>
        <mesh
          filename="package://bigmama0314/meshes/Link_4.STL" />
      </geometry>
    </collision>
  </link>
  <joint
    name="Joint_4"
    type="revolute">
    <origin
      xyz="0 0.145 0.022"
      rpy="1.5708 0 0" />
    <parent
      link="Link_3" />
    <child
      link="Link_4" />
    <axis
      xyz="0 0 -1" />
    <limit
      lower="0"
      upper="0.0001"
      effort="0"
      velocity="0" />
    <dynamics
      damping="10"
      friction="10" />
  </joint>
  <link
    name="Link_forwardsucker">
    <inertial>
      <origin
        xyz="0.00021444 -4.3723E-08 -0.00013148"
        rpy="0 0 0" />
      <mass
        value="0.088134" />
      <inertia
        ixx="3.7615E-05"
        ixy="4.0865E-11"
        ixz="-1.9138E-07"
        iyy="3.3338E-05"
        iyz="-3.6828E-11"
        izz="4.7149E-05" />
    </inertial>
    <visual>
      <origin
        xyz="0 0 0"
        rpy="0 0 0" />
      <geometry>
        <mesh
          filename="package://bigmama0314/meshes/Link_forwardsucker.STL" />
      </geometry>
      <material
        name="">
        <color
          rgba="0.79216 0.81961 0.93333 1" />
      </material>
    </visual>
    <collision>
      <origin
        xyz="0 0 0"
        rpy="0 0 0" />
      <geometry>
        <mesh
          filename="package://bigmama0314/meshes/Link_forwardsucker.STL" />
      </geometry>
    </collision>
  </link>
  <joint
    name="Joint_forwardsucker"
    type="revolute">
    <origin
      xyz="0.1 0 -0.035"
      rpy="0 0 0" />
    <parent
      link="Link_4" />
    <child
      link="Link_forwardsucker" />
    <axis
      xyz="0 0 -1" />
    <limit
      lower="0"
      upper="0.0001"
      effort="0"
      velocity="0" />
    <dynamics
      damping="10"
      friction="10" />
  </joint>
  <link
    name="Link_innerfinger">
    <inertial>
      <origin
        xyz="0.0005 -3.9302E-14 0.0037772"
        rpy="0 0 0" />
      <mass
        value="0.0006032" />
      <inertia
        ixx="2.9694E-07"
        ixy="-9.7786E-25"
        ixz="1.0619E-25"
        iyy="3.2374E-09"
        iyz="-1.1145E-22"
        izz="2.938E-07" />
    </inertial>
    <visual>
      <origin
        xyz="0 0 0"
        rpy="0 0 0" />
      <geometry>
        <mesh
          filename="package://bigmama0314/meshes/Link_innerfinger.STL" />
      </geometry>
      <material
        name="">
        <color
          rgba="0.79216 0.81961 0.93333 1" />
      </material>
    </visual>
    <collision>
      <origin
        xyz="0 0 0"
        rpy="0 0 0" />
      <geometry>
        <mesh
          filename="package://bigmama0314/meshes/Link_innerfinger.STL" />
      </geometry>
    </collision>
  </link>
  <joint
    name="Joint_innerfinger"
    type="prismatic">
    <origin
      xyz="0 -0.006 -0.015"
      rpy="0 0 1.5708" />
    <parent
      link="Link_forwardsucker" />
    <child
      link="Link_innerfinger" />
    <axis
      xyz="-1 0 0" />
    <limit
      lower="-0.005"
      upper="0.005"
      effort="50"
      velocity="0.05" />
  </joint>
  <link
    name="Link_exterfinger">
    <inertial>
      <origin
        xyz="-0.0005 -4.4742E-14 0.0037772"
        rpy="0 0 0" />
      <mass
        value="0.0006032" />
      <inertia
        ixx="2.9694E-07"
        ixy="1.6439E-24"
        ixz="-7.9781E-26"
        iyy="3.2374E-09"
        iyz="-5.7315E-24"
        izz="2.938E-07" />
    </inertial>
    <visual>
      <origin
        xyz="0 0 0"
        rpy="0 0 0" />
      <geometry>
        <mesh
          filename="package://bigmama0314/meshes/Link_exterfinger.STL" />
      </geometry>
      <material
        name="">
        <color
          rgba="0.79216 0.81961 0.93333 1" />
      </material>
    </visual>
    <collision>
      <origin
        xyz="0 0 0"
        rpy="0 0 0" />
      <geometry>
        <mesh
          filename="package://bigmama0314/meshes/Link_exterfinger.STL" />
      </geometry>
    </collision>
  </link>
  <joint
    name="Joint_exterfinger"
    type="prismatic">
    <origin
      xyz="0 0.006 -0.015"
      rpy="0 0 1.5708" />
    <parent
      link="Link_forwardsucker" />
    <child
      link="Link_exterfinger" />
    <axis
      xyz="-1 0 0" />
    <limit
      lower="-0.005"
      upper="0.005"
      effort="50"
      velocity="0.05" />
  </joint>
</robot>