<?xml version="1.0" encoding="utf-8"?>
<!-- This URDF was automatically created by SolidWorks to URDF Exporter! Originally created by Stephen Brawner (brawner@gmail.com) 
     Commit Version: 1.6.0-1-g15f4949  Build Version: 1.6.7594.29634
     For more information, please see http://wiki.ros.org/sw_urdf_exporter -->
<robot
  name="bigmama0404">
  <link
    name="Link_0">
    <inertial>
      <origin
        xyz="-0.00360067778183354 -0.00883720453207504 0.0292421918925886"
        rpy="0 0 0" />
      <mass
        value="0.810928179042901" />
      <inertia
        ixx="0.00149879110186889"
        ixy="-1.29470167277919E-05"
        ixz="1.42354816371536E-05"
        iyy="0.00144512079422282"
        iyz="-7.34227463023617E-06"
        izz="0.00102948039835816" />
    </inertial>
    <visual>
      <origin
        xyz="0 0 0"
        rpy="0 0 0" />
      <geometry>
        <mesh
          filename="package://bigmama0404/meshes/Link_0.STL" />
      </geometry>
      <material
        name="">
        <color
          rgba="0.792156862745098 0.819607843137255 0.933333333333333 1" />
      </material>
    </visual>
    <collision>
      <origin
        xyz="0 0 0"
        rpy="0 0 0" />
      <geometry>
        <mesh
          filename="package://bigmama0404/meshes/Link_0.STL" />
      </geometry>
    </collision>
  </link>
  <link
    name="Link_1">
    <inertial>
      <origin
        xyz="3.33066907387547E-16 0.120000000000001 0.0148133941875559"
        rpy="0 0 0" />
      <mass
        value="0.282384693513862" />
      <inertia
        ixx="0.00274447139440248"
        ixy="2.03761521701345E-19"
        ixz="-5.60290136516403E-21"
        iyy="0.000195078787164715"
        iyz="1.40857492210562E-20"
        izz="0.00291591183814071" />
    </inertial>
    <visual>
      <origin
        xyz="0 0 0"
        rpy="0 0 0" />
      <geometry>
        <mesh
          filename="package://bigmama0404/meshes/Link_1.STL" />
      </geometry>
      <material
        name="">
        <color
          rgba="0.792156862745098 0.819607843137255 0.933333333333333 1" />
      </material>
    </visual>
    <collision>
      <origin
        xyz="0 0 0"
        rpy="0 0 0" />
      <geometry>
        <mesh
          filename="package://bigmama0404/meshes/Link_1.STL" />
      </geometry>
    </collision>
  </link>
  <joint
    name="Joint_1"
    type="revolute">
    <origin
      xyz="0.022 0 0.155"
      rpy="1.5707963267949 0 1.5707963267949" />
    <parent
      link="Link_0" />
    <child
      link="Link_1" />
    <axis
      xyz="0 0 -1" />
    <limit
      lower="-3.14"
      upper="3.14"
      effort="500"
      velocity="0.05" />
  </joint>
  <link
    name="Link_2">
    <inertial>
      <origin
        xyz="5.55111512312578E-15 0.0981842440812921 -0.0518979671215241"
        rpy="0 0 0" />
      <mass
        value="0.345163663974144" />
      <inertia
        ixx="0.0036331910417201"
        ixy="3.23041910956552E-18"
        ixz="-4.48446716888843E-19"
        iyy="0.000344054038167575"
        iyz="0.000241150545790953"
        izz="0.00379142507539423" />
    </inertial>
    <visual>
      <origin
        xyz="0 0 0"
        rpy="0 0 0" />
      <geometry>
        <mesh
          filename="package://bigmama0404/meshes/Link_2.STL" />
      </geometry>
      <material
        name="">
        <color
          rgba="0.792156862745098 0.819607843137255 0.933333333333333 1" />
      </material>
    </visual>
    <collision>
      <origin
        xyz="0 0 0"
        rpy="0 0 0" />
      <geometry>
        <mesh
          filename="package://bigmama0404/meshes/Link_2.STL" />
      </geometry>
    </collision>
  </link>
  <joint
    name="Joint_2"
    type="revolute">
    <origin
      xyz="0 0.239999999999989 0"
      rpy="0 0 0" />
    <parent
      link="Link_1" />
    <child
      link="Link_2" />
    <axis
      xyz="0 0 -1" />
    <limit
      lower="-3.14"
      upper="3.14"
      effort="500"
      velocity="0.05" />
  </joint>
  <link
    name="Link_3">
    <inertial>
      <origin
        xyz="0.0182556388647203 0.077688167435717 0.0292189539257218"
        rpy="0 0 0" />
      <mass
        value="0.405243678629156" />
      <inertia
        ixx="0.0010066908609712"
        ixy="-1.02117053661611E-05"
        ixz="-1.29579969608816E-05"
        iyy="0.000277409370252715"
        iyz="1.42352093688465E-05"
        izz="0.00110247571714619" />
    </inertial>
    <visual>
      <origin
        xyz="0 0 0"
        rpy="0 0 0" />
      <geometry>
        <mesh
          filename="package://bigmama0404/meshes/Link_3.STL" />
      </geometry>
      <material
        name="">
        <color
          rgba="0.792156862745098 0.819607843137255 0.933333333333333 1" />
      </material>
    </visual>
    <collision>
      <origin
        xyz="0 0 0"
        rpy="0 0 0" />
      <geometry>
        <mesh
          filename="package://bigmama0404/meshes/Link_3.STL" />
      </geometry>
    </collision>
  </link>
  <joint
    name="Joint_3"
    type="revolute">
    <origin
      xyz="0 0.239999999999999 -0.0441999999999954"
      rpy="0 0 0" />
    <parent
      link="Link_2" />
    <child
      link="Link_3" />
    <axis
      xyz="0 0 1" />
    <limit
      lower="-3.14"
      upper="3.14"
      effort="500"
      velocity="0.05" />
  </joint>
  <link
    name="Link_4">
    <inertial>
      <origin
        xyz="-0.000571100099163613 -1.53255196832132E-05 -0.0288070807646197"
        rpy="0 0 0" />
      <mass
        value="0.405610108151776" />
      <inertia
        ixx="0.000438080420431632"
        ixy="1.32882114011324E-08"
        ixz="-2.85557702463612E-06"
        iyy="0.000395912370663264"
        iyz="7.13846572554124E-09"
        izz="0.000752016973569227" />
    </inertial>
    <visual>
      <origin
        xyz="0 0 0"
        rpy="0 0 0" />
      <geometry>
        <mesh
          filename="package://bigmama0404/meshes/Link_4.STL" />
      </geometry>
      <material
        name="">
        <color
          rgba="0.792156862745098 0.819607843137255 0.933333333333333 1" />
      </material>
    </visual>
    <collision>
      <origin
        xyz="0 0 0"
        rpy="0 0 0" />
      <geometry>
        <mesh
          filename="package://bigmama0404/meshes/Link_4.STL" />
      </geometry>
    </collision>
  </link>
  <joint
    name="Joint_4"
    type="revolute">
    <origin
      xyz="0 0.144999999999999 0.0220000000000023"
      rpy="1.5707963267949 0 0" />
    <parent
      link="Link_3" />
    <child
      link="Link_4" />
    <axis
      xyz="0 0 -1" />
    <limit
      lower="-1E-05"
      upper="1E-05"
      effort="1E-05"
      velocity="1E-05" />
  </joint>
  <link
    name="Link_innerfinger">
    <inertial>
      <origin
        xyz="-0.6723 1.1992 -0.005"
        rpy="0 0 0" />
      <mass
        value="0.26589" />
      <inertia
        ixx="0.10864"
        ixy="-0.01177"
        ixz="-3.9329E-10"
        iyy="0.028303"
        iyz="-4.3932E-10"
        izz="0.13678" />
    </inertial>
    <visual>
      <origin
        xyz="0 0 0"
        rpy="0 0 0" />
      <geometry>
        <mesh
          filename="package://bigmama0404/meshes/Link_innerfinger.STL" />
      </geometry>
      <material
        name="">
        <color
          rgba="0.79216 0.81961 0.93333 1" />
      </material>
    </visual>
    <collision>
      <origin
        xyz="0 0 0"
        rpy="0 0 0" />
      <geometry>
        <mesh
          filename="package://bigmama0404/meshes/Link_innerfinger.STL" />
      </geometry>
    </collision>
  </link>
  <joint
    name="Joint_innerfinger"
    type="revolute">
    <origin
      xyz="-0.005 -0.11247 0"
      rpy="-1.5708 0 1.5708" />
    <parent
      link="Link_4" />
    <child
      link="Link_innerfinger" />
    <axis
      xyz="0 0 1" />
    <limit
      lower="-3.14"
      upper="3.14"
      effort="500"
      velocity="0.05" />
  </joint>
  <link
    name="Link_exterfinger">
    <inertial>
      <origin
        xyz="0.6723 1.1992 -0.005"
        rpy="0 0 0" />
      <mass
        value="0.26589" />
      <inertia
        ixx="0.10864"
        ixy="0.01177"
        ixz="-3.9329E-10"
        iyy="0.028303"
        iyz="4.3932E-10"
        izz="0.13678" />
    </inertial>
    <visual>
      <origin
        xyz="0 0 0"
        rpy="0 0 0" />
      <geometry>
        <mesh
          filename="package://bigmama0404/meshes/Link_exterfinger.STL" />
      </geometry>
      <material
        name="">
        <color
          rgba="0.79216 0.81961 0.93333 1" />
      </material>
    </visual>
    <collision>
      <origin
        xyz="0 0 0"
        rpy="0 0 0" />
      <geometry>
        <mesh
          filename="package://bigmama0404/meshes/Link_exterfinger.STL" />
      </geometry>
    </collision>
  </link>
  <joint
    name="Joint_exterfinger"
    type="revolute">
    <origin
      xyz="-0.005 0.11247 0"
      rpy="-1.5708 0 1.5708" />
    <parent
      link="Link_4" />
    <child
      link="Link_exterfinger" />
    <axis
      xyz="0 0 -1" />
    <limit
      lower="-3.14"
      upper="3.14"
      effort="500"
      velocity="0.05" />
  </joint>
  <link
    name="Link_baseout">
    <inertial>
      <origin
        xyz="-0.6723 -1.1992 0.005"
        rpy="0 0 0" />
      <mass
        value="0.26589" />
      <inertia
        ixx="0.10864"
        ixy="0.01177"
        ixz="3.9329E-10"
        iyy="0.028303"
        iyz="-4.3932E-10"
        izz="0.13678" />
    </inertial>
    <visual>
      <origin
        xyz="0 0 0"
        rpy="0 0 0" />
      <geometry>
        <mesh
          filename="package://bigmama0404/meshes/Link_baseout.STL" />
      </geometry>
      <material
        name="">
        <color
          rgba="0.79216 0.81961 0.93333 1" />
      </material>
    </visual>
    <collision>
      <origin
        xyz="0 0 0"
        rpy="0 0 0" />
      <geometry>
        <mesh
          filename="package://bigmama0404/meshes/Link_baseout.STL" />
      </geometry>
    </collision>
  </link>
  <joint
    name="Joint_baseout"
    type="revolute">
    <origin
      xyz="-0.11247 0.005 0.01"
      rpy="1.5708 0 0" />
    <parent
      link="Link_0" />
    <child
      link="Link_baseout" />
    <axis
      xyz="0 0 -1" />
    <limit
      lower="-3.14"
      upper="3.14"
      effort="500"
      velocity="0.05" />
  </joint>
  <link
    name="Link_basein">
    <inertial>
      <origin
        xyz="0.6723 -1.1992 0.005"
        rpy="0 0 0" />
      <mass
        value="0.26589" />
      <inertia
        ixx="0.10864"
        ixy="-0.01177"
        ixz="3.9329E-10"
        iyy="0.028303"
        iyz="4.3932E-10"
        izz="0.13678" />
    </inertial>
    <visual>
      <origin
        xyz="0 0 0"
        rpy="0 0 0" />
      <geometry>
        <mesh
          filename="package://bigmama0404/meshes/Link_basein.STL" />
      </geometry>
      <material
        name="">
        <color
          rgba="0.79216 0.81961 0.93333 1" />
      </material>
    </visual>
    <collision>
      <origin
        xyz="0 0 0"
        rpy="0 0 0" />
      <geometry>
        <mesh
          filename="package://bigmama0404/meshes/Link_basein.STL" />
      </geometry>
    </collision>
  </link>
  <joint
    name="Joint_basein"
    type="revolute">
    <origin
      xyz="0.11247 0.005 0.01"
      rpy="1.5708 0 0" />
    <parent
      link="Link_0" />
    <child
      link="Link_basein" />
    <axis
      xyz="0 0 1" />
    <limit
      lower="-3.14"
      upper="3.14"
      effort="500"
      velocity="0.05" />
  </joint>
</robot>